Workbook

Sheet Auswertung
A2: Didi · Kalorienauswertung
A4: Zeitraum von | B4: 46290 | D4: Zeitraum gesamt | E4: Ø je erfasstem Tag | G4: Protein (g) | H4: Kohlenhydrate (g) | I4: Fett (g) | J4: Mahlzeiten
A5: Zeitraum bis | B5: 46291 | D5: =IF(B5<B4,"Datum prüfen",SUMIFS(Mahlzeiten!$D$2:$D$501,Mahlzeiten!$A$2:$A$501,">="&B4,Mahlzeiten!$A$2:$A$501,"<"&B5+1)) -> 1890 | E5: =IF(B5<B4,"Datum prüfen",IF(OR(B4<B7,B5>=B7+60),"Tagesliste anpassen",IF(COUNTIFS(Mahlzeiten!$A$2:$A$501,">="&B4,Mahlzeiten!$A$2:$A$501,"<"&B5+1)=0,"",D5/SUMPRODUCT((A20:A79>=B4)*(A20:A79<=B5)*(B20:B79<>""))))) -> 945 | G5: =IF($B$5<$B$4,"Datum prüfen",SUMIFS(Mahlzeiten!$E$2:$E$501,Mahlzeiten!$A$2:$A$501,">="&$B$4,Mahlzeiten!$A$2:$A$501,"<"&$B$5+1)) -> 99 | H5: =IF($B$5<$B$4,"Datum prüfen",SUMIFS(Mahlzeiten!$F$2:$F$501,Mahlzeiten!$A$2:$A$501,">="&$B$4,Mahlzeiten!$A$2:$A$501,"<"&$B$5+1)) -> 153 | I5: =IF($B$5<$B$4,"Datum prüfen",SUMIFS(Mahlzeiten!$G$2:$G$501,Mahlzeiten!$A$2:$A$501,">="&$B$4,Mahlzeiten!$A$2:$A$501,"<"&$B$5+1)) -> 96 | J5: =IF(B5<B4,"Datum prüfen",COUNTIFS(Mahlzeiten!$A$2:$A$501,">="&B4,Mahlzeiten!$A$2:$A$501,"<"&B5+1)) -> 2
A7: Tagesliste ab | B7: 46290
A10: Zeitraum: B4/B5 ändern · Tagesliste: B7 ändern · Neue Mahlzeiten im Blatt „Mahlzeiten“ aus gespeicherter didi-alle-tage.csv der App laden.
A11: Die Wochen beginnen montags. Leere Tage bleiben ohne Kalorienwert. Ø bezieht sich auf erfasste Tage in der Tagesliste.
A13: Tageswerte (60 Tage) | D13: Wochenwerte (12 Wochen)
A19: Datum | B19: kcal | D19: Woche ab Montag | E19: kcal
A20: =$B$7 -> 46290 | B20: =IF(COUNTIF(Mahlzeiten!$A$2:$A$501,A20)=0,"",SUMIF(Mahlzeiten!$A$2:$A$501,A20,Mahlzeiten!$D$2:$D$501)) -> 595 | D20: =A20-WEEKDAY(A20,2)+1 -> 46286 | E20: =IF(COUNTIFS(Mahlzeiten!$A$2:$A$501,">="&D20,Mahlzeiten!$A$2:$A$501,"<"&D20+7)=0,"",SUMIFS(Mahlzeiten!$D$2:$D$501,Mahlzeiten!$A$2:$A$501,">="&D20,Mahlzeiten!$A$2:$A$501,"<"&D20+7)) -> 1890
A21: =A20+1 -> 46291 | B21: =IF(COUNTIF(Mahlzeiten!$A$2:$A$501,A21)=0,"",SUMIF(Mahlzeiten!$A$2:$A$501,A21,Mahlzeiten!$D$2:$D$501)) -> 1295 | D21: =D20+7 -> 46293 | E21: =IF(COUNTIFS(Mahlzeiten!$A$2:$A$501,">="&D21,Mahlzeiten!$A$2:$A$501,"<"&D21+7)=0,"",SUMIFS(Mahlzeiten!$D$2:$D$501,Mahlzeiten!$A$2:$A$501,">="&D21,Mahlzeiten!$A$2:$A$501,"<"&D21+7))
A22: =A21+1 -> 46292 | B22: =IF(COUNTIF(Mahlzeiten!$A$2:$A$501,A22)=0,"",SUMIF(Mahlzeiten!$A$2:$A$501,A22,Mahlzeiten!$D$2:$D$501)) | D22: =D21+7 -> 46300 | E22: =IF(COUNTIFS(Mahlzeiten!$A$2:$A$501,">="&D22,Mahlzeiten!$A$2:$A$501,"<"&D22+7)=0,"",SUMIFS(Mahlzeiten!$D$2:$D$501,Mahlzeiten!$A$2:$A$501,">="&D22,Mahlzeiten!$A$2:$A$501,"<"&D22+7))
A23: =A22+1 -> 46293 | B23: =IF(COUNTIF(Mahlzeiten!$A$2:$A$501,A23)=0,"",SUMIF(Mahlzeiten!$A$2:$A$501,A23,Mahlzeiten!$D$2:$D$501)) | D23: =D22+7 -> 46307 | E23: =IF(COUNTIFS(Mahlzeiten!$A$2:$A$501,">="&D23,Mahlzeiten!$A$2:$A$501,"<"&D23+7)=0,"",SUMIFS(Mahlzeiten!$D$2:$D$501,Mahlzeiten!$A$2:$A$501,">="&D23,Mahlzeiten!$A$2:$A$501,"<"&D23+7))
A24: =A23+1 -> 46294 | B24: =IF(COUNTIF(Mahlzeiten!$A$2:$A$501,A24)=0,"",SUMIF(Mahlzeiten!$A$2:$A$501,A24,Mahlzeiten!$D$2:$D$501)) | D24: =D23+7 -> 46314 | E24: =IF(COUNTIFS(Mahlzeiten!$A$2:$A$501,">="&D24,Mahlzeiten!$A$2:$A$501,"<"&D24+7)=0,"",SUMIFS(Mahlzeiten!$D$2:$D$501,Mahlzeiten!$A$2:$A$501,">="&D24,Mahlzeiten!$A$2:$A$501,"<"&D24+7))
A25: =A24+1 -> 46295 | B25: =IF(COUNTIF(Mahlzeiten!$A$2:$A$501,A25)=0,"",SUMIF(Mahlzeiten!$A$2:$A$501,A25,Mahlzeiten!$D$2:$D$501)) | D25: =D24+7 -> 46321 | E25: =IF(COUNTIFS(Mahlzeiten!$A$2:$A$501,">="&D25,Mahlzeiten!$A$2:$A$501,"<"&D25+7)=0,"",SUMIFS(Mahlzeiten!$D$2:$D$501,Mahlzeiten!$A$2:$A$501,">="&D25,Mahlzeiten!$A$2:$A$501,"<"&D25+7))
A26: =A25+1 -> 46296 | B26: =IF(COUNTIF(Mahlzeiten!$A$2:$A$501,A26)=0,"",SUMIF(Mahlzeiten!$A$2:$A$501,A26,Mahlzeiten!$D$2:$D$501)) | D26: =D25+7 -> 46328 | E26: =IF(COUNTIFS(Mahlzeiten!$A$2:$A$501,">="&D26,Mahlzeiten!$A$2:$A$501,"<"&D26+7)=0,"",SUMIFS(Mahlzeiten!$D$2:$D$501,Mahlzeiten!$A$2:$A$501,">="&D26,Mahlzeiten!$A$2:$A$501,"<"&D26+7))
A27: =A26+1 -> 46297 | B27: =IF(COUNTIF(Mahlzeiten!$A$2:$A$501,A27)=0,"",SUMIF(Mahlzeiten!$A$2:$A$501,A27,Mahlzeiten!$D$2:$D$501)) | D27: =D26+7 -> 46335 | E27: =IF(COUNTIFS(Mahlzeiten!$A$2:$A$501,">="&D27,Mahlzeiten!$A$2:$A$501,"<"&D27+7)=0,"",SUMIFS(Mahlzeiten!$D$2:$D$501,Mahlzeiten!$A$2:$A$501,">="&D27,Mahlzeiten!$A$2:$A$501,"<"&D27+7))
A28: =A27+1 -> 46298 | B28: =IF(COUNTIF(Mahlzeiten!$A$2:$A$501,A28)=0,"",SUMIF(Mahlzeiten!$A$2:$A$501,A28,Mahlzeiten!$D$2:$D$501)) | D28: =D27+7 -> 46342 | E28: =IF(COUNTIFS(Mahlzeiten!$A$2:$A$501,">="&D28,Mahlzeiten!$A$2:$A$501,"<"&D28+7)=0,"",SUMIFS(Mahlzeiten!$D$2:$D$501,Mahlzeiten!$A$2:$A$501,">="&D28,Mahlzeiten!$A$2:$A$501,"<"&D28+7))
A29: =A28+1 -> 46299 | B29: =IF(COUNTIF(Mahlzeiten!$A$2:$A$501,A29)=0,"",SUMIF(Mahlzeiten!$A$2:$A$501,A29,Mahlzeiten!$D$2:$D$501)) | D29: =D28+7 -> 46349 | E29: =IF(COUNTIFS(Mahlzeiten!$A$2:$A$501,">="&D29,Mahlzeiten!$A$2:$A$501,"<"&D29+7)=0,"",SUMIFS(Mahlzeiten!$D$2:$D$501,Mahlzeiten!$A$2:$A$501,">="&D29,Mahlzeiten!$A$2:$A$501,"<"&D29+7))
A30: =A29+1 -> 46300 | B30: =IF(COUNTIF(Mahlzeiten!$A$2:$A$501,A30)=0,"",SUMIF(Mahlzeiten!$A$2:$A$501,A30,Mahlzeiten!$D$2:$D$501)) | D30: =D29+7 -> 46356 | E30: =IF(COUNTIFS(Mahlzeiten!$A$2:$A$501,">="&D30,Mahlzeiten!$A$2:$A$501,"<"&D30+7)=0,"",SUMIFS(Mahlzeiten!$D$2:$D$501,Mahlzeiten!$A$2:$A$501,">="&D30,Mahlzeiten!$A$2:$A$501,"<"&D30+7))
A31: =A30+1 -> 46301 | B31: =IF(COUNTIF(Mahlzeiten!$A$2:$A$501,A31)=0,"",SUMIF(Mahlzeiten!$A$2:$A$501,A31,Mahlzeiten!$D$2:$D$501)) | D31: =D30+7 -> 46363 | E31: =IF(COUNTIFS(Mahlzeiten!$A$2:$A$501,">="&D31,Mahlzeiten!$A$2:$A$501,"<"&D31+7)=0,"",SUMIFS(Mahlzeiten!$D$2:$D$501,Mahlzeiten!$A$2:$A$501,">="&D31,Mahlzeiten!$A$2:$A$501,"<"&D31+7))
A32: =A31+1 -> 46302 | B32: =IF(COUNTIF(Mahlzeiten!$A$2:$A$501,A32)=0,"",SUMIF(Mahlzeiten!$A$2:$A$501,A32,Mahlzeiten!$D$2:$D$501))
A33: =A32+1 -> 46303 | B33: =IF(COUNTIF(Mahlzeiten!$A$2:$A$501,A33)=0,"",SUMIF(Mahlzeiten!$A$2:$A$501,A33,Mahlzeiten!$D$2:$D$501))
A34: =A33+1 -> 46304 | B34: =IF(COUNTIF(Mahlzeiten!$A$2:$A$501,A34)=0,"",SUMIF(Mahlzeiten!$A$2:$A$501,A34,Mahlzeiten!$D$2:$D$501))
A35: =A34+1 -> 46305 | B35: =IF(COUNTIF(Mahlzeiten!$A$2:$A$501,A35)=0,"",SUMIF(Mahlzeiten!$A$2:$A$501,A35,Mahlzeiten!$D$2:$D$501))
A36: =A35+1 -> 46306 | B36: =IF(COUNTIF(Mahlzeiten!$A$2:$A$501,A36)=0,"",SUMIF(Mahlzeiten!$A$2:$A$501,A36,Mahlzeiten!$D$2:$D$501))
A37: =A36+1 -> 46307 | B37: =IF(COUNTIF(Mahlzeiten!$A$2:$A$501,A37)=0,"",SUMIF(Mahlzeiten!$A$2:$A$501,A37,Mahlzeiten!$D$2:$D$501))
A38: =A37+1 -> 46308 | B38: =IF(COUNTIF(Mahlzeiten!$A$2:$A$501,A38)=0,"",SUMIF(Mahlzeiten!$A$2:$A$501,A38,Mahlzeiten!$D$2:$D$501))
A39: =A38+1 -> 46309 | B39: =IF(COUNTIF(Mahlzeiten!$A$2:$A$501,A39)=0,"",SUMIF(Mahlzeiten!$A$2:$A$501,A39,Mahlzeiten!$D$2:$D$501))
A40: =A39+1 -> 46310 | B40: =IF(COUNTIF(Mahlzeiten!$A$2:$A$501,A40)=0,"",SUMIF(Mahlzeiten!$A$2:$A$501,A40,Mahlzeiten!$D$2:$D$501))
A41: =A40+1 -> 46311 | B41: =IF(COUNTIF(Mahlzeiten!$A$2:$A$501,A41)=0,"",SUMIF(Mahlzeiten!$A$2:$A$501,A41,Mahlzeiten!$D$2:$D$501))
A42: =A41+1 -> 46312 | B42: =IF(COUNTIF(Mahlzeiten!$A$2:$A$501,A42)=0,"",SUMIF(Mahlzeiten!$A$2:$A$501,A42,Mahlzeiten!$D$2:$D$501))
A43: =A42+1 -> 46313 | B43: =IF(COUNTIF(Mahlzeiten!$A$2:$A$501,A43)=0,"",SUMIF(Mahlzeiten!$A$2:$A$501,A43,Mahlzeiten!$D$2:$D$501))
... A58: =A57+1 -> 46328 | B58: =IF(COUNTIF(Mahlzeiten!$A$2:$A$501,A58)=0,"",SUMIF(Mahlzeiten!$A$2:$A$501,A58,Mahlzeiten!$D$2:$D$501))
A59: =A58+1 -> 46329 | B59: =IF(COUNTIF(Mahlzeiten!$A$2:$A$501,A59)=0,"",SUMIF(Mahlzeiten!$A$2:$A$501,A59,Mahlzeiten!$D$2:$D$501)) | G59: Tag | H59: kcal | J59: Woche | K59: kcal
A60: =A59+1 -> 46330 | B60: =IF(COUNTIF(Mahlzeiten!$A$2:$A$501,A60)=0,"",SUMIF(Mahlzeiten!$A$2:$A$501,A60,Mahlzeiten!$D$2:$D$501)) | G60: =RIGHT("0"&DAY(A20),2)&"."&RIGHT("0"&MONTH(A20),2) -> 25.09 | H60: =B20 -> 595 | J60: =RIGHT("0"&DAY(D20),2)&"."&RIGHT("0"&MONTH(D20),2) -> 21.09 | K60: =E20 -> 1890
A61: =A60+1 -> 46331 | B61: =IF(COUNTIF(Mahlzeiten!$A$2:$A$501,A61)=0,"",SUMIF(Mahlzeiten!$A$2:$A$501,A61,Mahlzeiten!$D$2:$D$501)) | G61: =RIGHT("0"&DAY(A21),2)&"."&RIGHT("0"&MONTH(A21),2) -> 26.09 | H61: =B21 -> 1295 | J61: =RIGHT("0"&DAY(D21),2)&"."&RIGHT("0"&MONTH(D21),2) -> 28.09 | K61: =E21 -> 0
A62: =A61+1 -> 46332 | B62: =IF(COUNTIF(Mahlzeiten!$A$2:$A$501,A62)=0,"",SUMIF(Mahlzeiten!$A$2:$A$501,A62,Mahlzeiten!$D$2:$D$501)) | G62: =RIGHT("0"&DAY(A22),2)&"."&RIGHT("0"&MONTH(A22),2) -> 27.09 | H62: =B22 -> 0 | J62: =RIGHT("0"&DAY(D22),2)&"."&RIGHT("0"&MONTH(D22),2) -> 05.10 | K62: =E22 -> 0
A63: =A62+1 -> 46333 | B63: =IF(COUNTIF(Mahlzeiten!$A$2:$A$501,A63)=0,"",SUMIF(Mahlzeiten!$A$2:$A$501,A63,Mahlzeiten!$D$2:$D$501)) | G63: =RIGHT("0"&DAY(A23),2)&"."&RIGHT("0"&MONTH(A23),2) -> 28.09 | H63: =B23 -> 0 | J63: =RIGHT("0"&DAY(D23),2)&"."&RIGHT("0"&MONTH(D23),2) -> 12.10 | K63: =E23 -> 0
A64: =A63+1 -> 46334 | B64: =IF(COUNTIF(Mahlzeiten!$A$2:$A$501,A64)=0,"",SUMIF(Mahlzeiten!$A$2:$A$501,A64,Mahlzeiten!$D$2:$D$501)) | G64: =RIGHT("0"&DAY(A24),2)&"."&RIGHT("0"&MONTH(A24),2) -> 29.09 | H64: =B24 -> 0 | J64: =RIGHT("0"&DAY(D24),2)&"."&RIGHT("0"&MONTH(D24),2) -> 19.10 | K64: =E24 -> 0
A65: =A64+1 -> 46335 | B65: =IF(COUNTIF(Mahlzeiten!$A$2:$A$501,A65)=0,"",SUMIF(Mahlzeiten!$A$2:$A$501,A65,Mahlzeiten!$D$2:$D$501)) | G65: =RIGHT("0"&DAY(A25),2)&"."&RIGHT("0"&MONTH(A25),2) -> 30.09 | H65: =B25 -> 0 | J65: =RIGHT("0"&DAY(D25),2)&"."&RIGHT("0"&MONTH(D25),2) -> 26.10 | K65: =E25 -> 0
...

Sheet Mahlzeiten
A1: Datum | B1: Mahlzeit | C1: ID | D1: kcal | E1: Protein (g) | F1: Kohlenhydrate (g) | G1: Fett (g)
A2: 46290 | B2: Gebratene Kartoffeln + Zucchini, gebraten | C2: 85e4fd29-0f12-404b-a17b-dbf2618a10f2 | D2: 595 | E2: 41 | F2: 36 | G2: 31
A3: 46291 | B3: Paniertes, gebratenes Schnitzel (zwei Stück, zusammen geschätzt) + Pommes frites | C3: 6ddf76b3-3936-4b42-a51b-9df001a08e72 | D3: 1295 | E3: 58 | F3: 117 | G3: 65
